<?xml version="1.0" encoding="utf-8"?>
<!-- =================================================================================== -->
<!-- |    This document was autogenerated by xacro from viper_two_robots.xacro         | -->
<!-- |    EDITING THIS FILE BY HAND IS NOT RECOMMENDED                                 | -->
<!-- =================================================================================== -->
<robot name="viper_robot" xmlns:controller="http://playerstage.sourceforge.net/gazebo/xmlschema/#controller" xmlns:interface="http://playerstage.sourceforge.net/gazebo/xmlschema/#interface" xmlns:sensor="http://playerstage.sourceforge.net/gazebo/xmlschema/#sensor" xmlns:xacro="http://www.ros.org/wiki/xacro">
  <gazebo>
    <!-- Load the joint control plugin -->
    <plugin filename="libgazebo_joint_control.so" name="gzplugin_joint_control">
      <robot_components_namespace>
          viper 
      </robot_components_namespace>
    </plugin>
    <!-- Load the joint state controller client -->
    <!-- will subscribe to topic read from ROS parameter publish_joint_states_topic -->
    <plugin filename="libgazebo_joint_state_client.so" name="gzplugin_joint_state_client">
      <robot_components_namespace>
          viper 
      </robot_components_namespace>
    </plugin>
    <plugin filename="libgazebo_joint_trajectory_server.so" name="gzplugin_joint_trajectory_server">
      <robot_components_namespace>
            viper 
        </robot_components_namespace>
      <trajectory_param_namespace>
            viper 
        </trajectory_param_namespace>
    </plugin>
  </gazebo>
  <!-- Limits  -->
  <!-- ......................... -->
  <!-- ......................... -->
  <!-- Robot transform -->
  <link name="base"/>
  <joint name="base_link-base" type="fixed">
    <origin rpy="0 0 0" xyz="0 0 0"/>
    <parent link="base"/>
    <child link="base_link"/>
  </joint>
  <!-- ___________________Material gazebo colors____________ -->
  <gazebo reference="base_link">
    <material>Gazebo/FlatBlack</material>
    <mu1>100000</mu1>
    <mu2>100000</mu2>
    <kp>100000000.0</kp>
    <kd>1.0</kd>
  </gazebo>
  <gazebo reference="link_1">
    <material>Gazebo/Grey</material>
    <mu1>100000</mu1>
    <mu2>100000</mu2>
    <kp>100000000.0</kp>
    <kd>1.0</kd>
  </gazebo>
  <gazebo reference="link_2">
    <material>Gazebo/Grey</material>
    <mu1>100000</mu1>
    <mu2>100000</mu2>
    <kp>100000000.0</kp>
    <kd>1.0</kd>
  </gazebo>
  <gazebo reference="link_3">
    <material>Gazebo/Grey</material>
    <mu1>100000</mu1>
    <mu2>100000</mu2>
    <kp>100000000.0</kp>
    <kd>1.0</kd>
  </gazebo>
  <gazebo reference="link_4">
    <material>Gazebo/Grey</material>
    <mu1>100000</mu1>
    <mu2>100000</mu2>
    <kp>100000000.0</kp>
    <kd>1.0</kd>
  </gazebo>
  <gazebo reference="link_5">
    <material>Gazebo/Grey</material>
    <mu1>100000</mu1>
    <mu2>100000</mu2>
    <kp>100000000.0</kp>
    <kd>1.0</kd>
  </gazebo>
  <gazebo reference="link_6">
    <material>Gazebo/Grey</material>
    <mu1>100000</mu1>
    <mu2>100000</mu2>
    <kp>100000000.0</kp>
    <kd>1.0</kd>
  </gazebo>
  <gazebo reference="tool0">
    <provideFeedback value="true"/>
  </gazebo>
  <!-- ...................................................... -->
  <!-- link list -->
  <link name="base_link">
    <inertial>
      <mass value="80.0"/>
      <inertia ixx="0.1" ixy="0" ixz="0" iyy="0.1" iyz="0" izz="0.1"/>
    </inertial>
    <visual>
      <origin rpy="0 0 0" xyz="0 0 0"/>
      <geometry>
        <mesh filename="package://viper_description/meshes/viper_s650/visual/base_link.stl" scale="0.001 0.001 0.001"/>
      </geometry>
      <material name="grey">
        <color rgba=".30 .30 .30 1"/>
      </material>
    </visual>
    <collision>
      <origin rpy="0 0 0" xyz="0 0 0"/>
      <geometry>
        <mesh filename="package://viper_description/meshes/viper_s650/collision/base_link.stl" scale="0.001 0.001 0.001"/>
      </geometry>
    </collision>
  </link>
  <link name="link_1">
    <inertial>
      <mass value="10.0"/>
      <inertia ixx="-3.490764925389290381e-17" ixy="5.326155553052944350e-17" ixz="-5.716810041401498782e-18" iyy="0.1" iyz="0" izz="8.791807962382938157e-01"/>
    </inertial>
    <visual>
      <origin rpy="0 0 0" xyz="0 0 0"/>
      <geometry>
        <mesh filename="package://viper_description/meshes/viper_s650/visual/link_1.stl" scale="0.001 0.001 0.001"/>
      </geometry>
      <material name="grey"/>
    </visual>
    <collision>
      <origin rpy="0 0 0" xyz="0 0 0"/>
      <geometry>
        <mesh filename="package://viper_description/meshes/viper_s650/collision/link_1.stl" scale="0.001 0.001 0.001"/>
      </geometry>
    </collision>
  </link>
  <link name="link_2">
    <inertial>
      <mass value="4.945391978840408403e-03"/>
      <inertia ixx="1.335802497117074272e-01" ixy="7.245061719661968769e-02" ixz="-5.712263185192772985e-02" iyy="7.456005465265865828e-01" iyz="2.958153083685036502e-02" izz="1.533043250753959974e+00"/>
    </inertial>
    <visual>
      <origin rpy="0 0 0" xyz="0 0 0"/>
      <geometry>
        <mesh filename="package://viper_description/meshes/viper_s650/visual/link_2.stl" scale="0.001 0.001 0.001"/>
      </geometry>
      <material name="grey"/>
    </visual>
    <collision>
      <origin rpy="0 0 0" xyz="0 0 0"/>
      <geometry>
        <mesh filename="package://viper_description/meshes/viper_s650/collision/link_2.stl" scale="0.001 0.001 0.001"/>
      </geometry>
    </collision>
  </link>
  <link name="link_3">
    <inertial>
      <mass value="8.078580607463647922e-01"/>
      <inertia ixx="2.331208911088874514e-01" ixy="-1.090807844958952000e-02" ixz="-2.428300873824706593e-02" iyy="6.460599051294060313e-01" iyz="-3.656073183070089605e-02" izz="-2.351809491161779841e-02"/>
    </inertial>
    <visual>
      <origin rpy="0 0 0" xyz="0 0 0"/>
      <geometry>
        <mesh filename="package://viper_description/meshes/viper_s650/visual/link_3.stl" scale="0.001 0.001 0.001"/>
      </geometry>
      <material name="grey"/>
      0,00
			
    </visual>
    <collision>
      <origin rpy="0 0 0" xyz="0 0 0"/>
      <geometry>
        <mesh filename="package://viper_description/meshes/viper_s650/collision/link_3.stl" scale="0.001 0.001 0.001"/>
      </geometry>
    </collision>
  </link>
  <link name="link_4">
    <inertial>
      <mass value="8.584276480588468594e-01"/>
      <inertia ixx="1.103401144951884072e-01" ixy="8.984920011033349987e-03" ixz="9.540383832482173844e-04" iyy="9.926268170208121799e-02" iyz="-2.261213869285401759e-02" izz="-4.411245156330630135e-02"/>
    </inertial>
    <visual>
      <origin rpy="0 0 0" xyz="0 0 0"/>
      <geometry>
        <mesh filename="package://viper_description/meshes/viper_s650/visual/link_4.stl" scale="0.001 0.001 0.001"/>
      </geometry>
      <material name="grey"/>
    </visual>
    <collision>
      <origin rpy="0 0 0" xyz="0 0 0"/>
      <geometry>
        <mesh filename="package://viper_description/meshes/viper_s650/collision/link_4.stl" scale="0.001 0.001 0.001"/>
      </geometry>
    </collision>
  </link>
  <link name="link_5">
    <inertial>
      <mass value="8.584276480588468594e-01"/>
      <inertia ixx="2.693461758178664414e-02" ixy="1.947912196665040757e-02" ixz="-3.400898655904057918e-03" iyy="3.929304535009547211e-02" iyz="-4.259669803201390596e-03" izz="5.681801088551182224e-03"/>
    </inertial>
    <visual>
      <origin rpy="0 0 0" xyz="0 0 0"/>
      <geometry>
        <mesh filename="package://viper_description/meshes/viper_s650/visual/link_5.stl" scale="0.001 0.001 0.001"/>
      </geometry>
      <material name="grey"/>
    </visual>
    <collision>
      <origin rpy="0 0 0" xyz="0 0 0"/>
      <geometry>
        <mesh filename="package://viper_description/meshes/viper_s650/collision/link_5.stl" scale="0.001 0.001 0.001"/>
      </geometry>
    </collision>
  </link>
  <link name="link_6">
    <inertial>
      <mass value="8.584276480588467484e-01"/>
      <inertia ixx="2.151269238524625843e-02" ixy="-4.276424685439520271e-03" ixz="-8.615986386512068836e-04" iyy="1.110372628509164426e-02" iyz="-5.984401221815184579e-03" izz="-4.132087197208047201e-03"/>
    </inertial>
    <visual>
      <origin rpy="0 0 0" xyz="0 0 0"/>
      <geometry>
        <mesh filename="package://viper_description/meshes/viper_s650/visual/link_6.stl" scale="0.001 0.001 0.001"/>
      </geometry>
      <material name="grey"/>
    </visual>
    <collision>
      <origin rpy="0 0 0" xyz="0 0 0"/>
      <geometry>
        <mesh filename="package://viper_description/meshes/viper_s650/collision/link_6.stl" scale="0.001 0.001 0.001"/>
      </geometry>
    </collision>
  </link>
  <link name="tool0">
    <inertial>
      <mass value="10.0"/>
      <origin rpy=" 0 0 0" xyz="0.0 0 0"/>
      <inertia ixx="0.1" ixy="0" ixz="0" iyy="0.1" iyz="0" izz="0.1"/>
    </inertial>
  </link>
  <!-- end of the link list -->
  <!-- join list -->
  <!-- ROS base_link to Adept World Coordinates transform -->
  <joint name="joint_1" type="revolute">
    <origin rpy="0 0 0" xyz="0 0 0.203"/>
    <parent link="base_link"/>
    <child link="link_1"/>
    <axis xyz="0 0 1"/>
    <limit effort="0" lower="-2.9671" upper="2.9671" velocity="5.7247"/>
    <dynamics damping="0.7"/>
  </joint>
  <joint name="joint_2" type="revolute">
    <origin rpy="0 0 0" xyz="0.075 0 0.132"/>
    <parent link="link_1"/>
    <child link="link_2"/>
    <axis xyz="0 1 0"/>
    <limit effort="0" lower="-3.3161" upper="0.7854" velocity="5.2360"/>
    <dynamics damping="0.7"/>
  </joint>
  <joint name="joint_3" type="revolute">
    <origin rpy="0 0 0" xyz="0.270 0 0"/>
    <parent link="link_2"/>
    <child link="link_3"/>
    <axis xyz="0 1 0"/>
    <limit effort="0" lower="-0.5061" upper="4.4680" velocity="6.5450"/>
    <dynamics damping="0.7"/>
  </joint>
  <joint name="joint_4" type="revolute">
    <origin rpy="0 0 0" xyz="-0.09 0 0.108"/>
    <parent link="link_3"/>
    <child link="link_4"/>
    <axis xyz="0 0 1"/>
    <limit effort="0" lower="-3.3161" upper="3.3161" velocity="6.5450"/>
    <dynamics damping="0.7"/>
  </joint>
  <joint name="joint_5" type="revolute">
    <origin rpy="0 0 0" xyz="0 0 0.187"/>
    <parent link="link_4"/>
    <child link="link_5"/>
    <axis xyz="0 1 0"/>
    <limit effort="0" lower="-2.0944" upper="2.0944" velocity="6.54"/>
    <dynamics damping="0.7"/>
  </joint>
  <joint name="joint_6" type="revolute">
    <origin rpy="0 0 0" xyz="0 0 0.080"/>
    <parent link="link_5"/>
    <child link="link_6"/>
    <axis xyz="0 0 1"/>
    <limit effort="0" lower="-6.2832" upper="6.2832" velocity="10.4720"/>
    <dynamics damping="0.7"/>
  </joint>
  <joint name="joint_6-tool0" type="fixed">
    <origin rpy="0 0 0" xyz="0 0 0.0"/>
    <parent link="link_6"/>
    <child link="tool0"/>
  </joint>
  <!-- end of the joint list -->
  <gazebo>
    <plugin filename="libgazebo_ros_contol.so" name="gazebo_ros_control">
 			</plugin>
  </gazebo>
  <!-- Robot transform -->
  <link name="base"/>
  <joint name="base_link-base" type="fixed">
    <origin rpy="0 0 0" xyz="0 0 0"/>
    <parent link="base"/>
    <child link="two_base_link"/>
  </joint>
  <!-- ___________________Material gazebo colors____________ -->
  <gazebo reference="two_base_link">
    <material>Gazebo/FlatBlack</material>
    <mu1>100000</mu1>
    <mu2>100000</mu2>
    <kp>100000000.0</kp>
    <kd>1.0</kd>
  </gazebo>
  <gazebo reference="two_link_1">
    <material>Gazebo/Grey</material>
    <mu1>100000</mu1>
    <mu2>100000</mu2>
    <kp>100000000.0</kp>
    <kd>1.0</kd>
  </gazebo>
  <gazebo reference="two_link_2">
    <material>Gazebo/Grey</material>
    <mu1>100000</mu1>
    <mu2>100000</mu2>
    <kp>100000000.0</kp>
    <kd>1.0</kd>
  </gazebo>
  <gazebo reference="two_link_3">
    <material>Gazebo/Grey</material>
    <mu1>100000</mu1>
    <mu2>100000</mu2>
    <kp>100000000.0</kp>
    <kd>1.0</kd>
  </gazebo>
  <gazebo reference="two_link_4">
    <material>Gazebo/Grey</material>
    <mu1>100000</mu1>
    <mu2>100000</mu2>
    <kp>100000000.0</kp>
    <kd>1.0</kd>
  </gazebo>
  <gazebo reference="two_link_5">
    <material>Gazebo/Grey</material>
    <mu1>100000</mu1>
    <mu2>100000</mu2>
    <kp>100000000.0</kp>
    <kd>1.0</kd>
  </gazebo>
  <gazebo reference="two_link_6">
    <material>Gazebo/Grey</material>
    <mu1>100000</mu1>
    <mu2>100000</mu2>
    <kp>100000000.0</kp>
    <kd>1.0</kd>
  </gazebo>
  <gazebo reference="two_tool0">
    <provideFeedback value="true"/>
  </gazebo>
  <!-- ...................................................... -->
  <!-- link list -->
  <link name="two_base_link">
    <inertial>
      <mass value="80.0"/>
      <inertia ixx="0.1" ixy="0" ixz="0" iyy="0.1" iyz="0" izz="0.1"/>
    </inertial>
    <visual>
      <origin rpy="0 0 0" xyz="0 0 0"/>
      <geometry>
        <mesh filename="package://viper_description/meshes/viper_s650/visual/base_link.stl" scale="0.001 0.001 0.001"/>
      </geometry>
      <material name="grey">
        <color rgba=".30 .30 .30 1"/>
      </material>
    </visual>
    <collision>
      <origin rpy="0 0 0" xyz="0 0 0"/>
      <geometry>
        <mesh filename="package://viper_description/meshes/viper_s650/collision/base_link.stl" scale="0.001 0.001 0.001"/>
      </geometry>
    </collision>
  </link>
  <link name="two_link_1">
    <inertial>
      <mass value="10.0"/>
      <inertia ixx="-3.490764925389290381e-17" ixy="5.326155553052944350e-17" ixz="-5.716810041401498782e-18" iyy="0.1" iyz="0" izz="8.791807962382938157e-01"/>
    </inertial>
    <visual>
      <origin rpy="0 0 0" xyz="0 0 0"/>
      <geometry>
        <mesh filename="package://viper_description/meshes/viper_s650/visual/link_1.stl" scale="0.001 0.001 0.001"/>
      </geometry>
      <material name="grey"/>
    </visual>
    <collision>
      <origin rpy="0 0 0" xyz="0 0 0"/>
      <geometry>
        <mesh filename="package://viper_description/meshes/viper_s650/collision/link_1.stl" scale="0.001 0.001 0.001"/>
      </geometry>
    </collision>
  </link>
  <link name="two_link_2">
    <inertial>
      <mass value="4.945391978840408403e-03"/>
      <inertia ixx="1.335802497117074272e-01" ixy="7.245061719661968769e-02" ixz="-5.712263185192772985e-02" iyy="7.456005465265865828e-01" iyz="2.958153083685036502e-02" izz="1.533043250753959974e+00"/>
    </inertial>
    <visual>
      <origin rpy="0 0 0" xyz="0 0 0"/>
      <geometry>
        <mesh filename="package://viper_description/meshes/viper_s650/visual/link_2.stl" scale="0.001 0.001 0.001"/>
      </geometry>
      <material name="grey"/>
    </visual>
    <collision>
      <origin rpy="0 0 0" xyz="0 0 0"/>
      <geometry>
        <mesh filename="package://viper_description/meshes/viper_s650/collision/link_2.stl" scale="0.001 0.001 0.001"/>
      </geometry>
    </collision>
  </link>
  <link name="two_link_3">
    <inertial>
      <mass value="8.078580607463647922e-01"/>
      <inertia ixx="2.331208911088874514e-01" ixy="-1.090807844958952000e-02" ixz="-2.428300873824706593e-02" iyy="6.460599051294060313e-01" iyz="-3.656073183070089605e-02" izz="-2.351809491161779841e-02"/>
    </inertial>
    <visual>
      <origin rpy="0 0 0" xyz="0 0 0"/>
      <geometry>
        <mesh filename="package://viper_description/meshes/viper_s650/visual/link_3.stl" scale="0.001 0.001 0.001"/>
      </geometry>
      <material name="grey"/>
      0,00
			
    </visual>
    <collision>
      <origin rpy="0 0 0" xyz="0 0 0"/>
      <geometry>
        <mesh filename="package://viper_description/meshes/viper_s650/collision/link_3.stl" scale="0.001 0.001 0.001"/>
      </geometry>
    </collision>
  </link>
  <link name="two_link_4">
    <inertial>
      <mass value="8.584276480588468594e-01"/>
      <inertia ixx="1.103401144951884072e-01" ixy="8.984920011033349987e-03" ixz="9.540383832482173844e-04" iyy="9.926268170208121799e-02" iyz="-2.261213869285401759e-02" izz="-4.411245156330630135e-02"/>
    </inertial>
    <visual>
      <origin rpy="0 0 0" xyz="0 0 0"/>
      <geometry>
        <mesh filename="package://viper_description/meshes/viper_s650/visual/link_4.stl" scale="0.001 0.001 0.001"/>
      </geometry>
      <material name="grey"/>
    </visual>
    <collision>
      <origin rpy="0 0 0" xyz="0 0 0"/>
      <geometry>
        <mesh filename="package://viper_description/meshes/viper_s650/collision/link_4.stl" scale="0.001 0.001 0.001"/>
      </geometry>
    </collision>
  </link>
  <link name="two_link_5">
    <inertial>
      <mass value="8.584276480588468594e-01"/>
      <inertia ixx="2.693461758178664414e-02" ixy="1.947912196665040757e-02" ixz="-3.400898655904057918e-03" iyy="3.929304535009547211e-02" iyz="-4.259669803201390596e-03" izz="5.681801088551182224e-03"/>
    </inertial>
    <visual>
      <origin rpy="0 0 0" xyz="0 0 0"/>
      <geometry>
        <mesh filename="package://viper_description/meshes/viper_s650/visual/link_5.stl" scale="0.001 0.001 0.001"/>
      </geometry>
      <material name="grey"/>
    </visual>
    <collision>
      <origin rpy="0 0 0" xyz="0 0 0"/>
      <geometry>
        <mesh filename="package://viper_description/meshes/viper_s650/collision/link_5.stl" scale="0.001 0.001 0.001"/>
      </geometry>
    </collision>
  </link>
  <link name="two_link_6">
    <inertial>
      <mass value="8.584276480588467484e-01"/>
      <inertia ixx="2.151269238524625843e-02" ixy="-4.276424685439520271e-03" ixz="-8.615986386512068836e-04" iyy="1.110372628509164426e-02" iyz="-5.984401221815184579e-03" izz="-4.132087197208047201e-03"/>
    </inertial>
    <visual>
      <origin rpy="0 0 0" xyz="0 0 0"/>
      <geometry>
        <mesh filename="package://viper_description/meshes/viper_s650/visual/link_6.stl" scale="0.001 0.001 0.001"/>
      </geometry>
      <material name="grey"/>
    </visual>
    <collision>
      <origin rpy="0 0 0" xyz="0 0 0"/>
      <geometry>
        <mesh filename="package://viper_description/meshes/viper_s650/collision/link_6.stl" scale="0.001 0.001 0.001"/>
      </geometry>
    </collision>
  </link>
  <link name="two_tool0">
    <inertial>
      <mass value="10.0"/>
      <origin rpy=" 0 0 0" xyz="0.0 0 0"/>
      <inertia ixx="0.1" ixy="0" ixz="0" iyy="0.1" iyz="0" izz="0.1"/>
    </inertial>
  </link>
  <!-- end of the link list -->
  <!-- join list -->
  <!-- ROS base_link to Adept World Coordinates transform -->
  <joint name="two_joint_1" type="revolute">
    <origin rpy="0 0 0" xyz="0 0 0.203"/>
    <parent link="two_base_link"/>
    <child link="two_link_1"/>
    <axis xyz="0 0 1"/>
    <limit effort="0" lower="-2.9671" upper="2.9671" velocity="5.7247"/>
    <dynamics damping="0.7"/>
  </joint>
  <joint name="two_joint_2" type="revolute">
    <origin rpy="0 0 0" xyz="0.075 0 0.132"/>
    <parent link="two_link_1"/>
    <child link="two_link_2"/>
    <axis xyz="0 1 0"/>
    <limit effort="0" lower="-3.3161" upper="0.7854" velocity="5.2360"/>
    <dynamics damping="0.7"/>
  </joint>
  <joint name="two_joint_3" type="revolute">
    <origin rpy="0 0 0" xyz="0.270 0 0"/>
    <parent link="two_link_2"/>
    <child link="two_link_3"/>
    <axis xyz="0 1 0"/>
    <limit effort="0" lower="-0.5061" upper="4.4680" velocity="6.5450"/>
    <dynamics damping="0.7"/>
  </joint>
  <joint name="two_joint_4" type="revolute">
    <origin rpy="0 0 0" xyz="-0.09 0 0.108"/>
    <parent link="two_link_3"/>
    <child link="two_link_4"/>
    <axis xyz="0 0 1"/>
    <limit effort="0" lower="-3.3161" upper="3.3161" velocity="6.5450"/>
    <dynamics damping="0.7"/>
  </joint>
  <joint name="two_joint_5" type="revolute">
    <origin rpy="0 0 0" xyz="0 0 0.187"/>
    <parent link="two_link_4"/>
    <child link="two_link_5"/>
    <axis xyz="0 1 0"/>
    <limit effort="0" lower="-2.0944" upper="2.0944" velocity="6.54"/>
    <dynamics damping="0.7"/>
  </joint>
  <joint name="two_joint_6" type="revolute">
    <origin rpy="0 0 0" xyz="0 0 0.080"/>
    <parent link="two_link_5"/>
    <child link="two_link_6"/>
    <axis xyz="0 0 1"/>
    <limit effort="0" lower="-6.2832" upper="6.2832" velocity="10.4720"/>
    <dynamics damping="0.7"/>
  </joint>
  <joint name="two_joint_6-tool0" type="fixed">
    <origin rpy="0 0 0" xyz="0 0 0.0"/>
    <parent link="two_link_6"/>
    <child link="two_tool0"/>
  </joint>
  <!-- end of the joint list -->
  <gazebo>
    <plugin filename="libgazebo_ros_contol.so" name="gazebo_ros_control">
 			</plugin>
  </gazebo>
</robot>

